<?xml version="1.0" encoding="UTF-8"?>
<testng-results skipped="0" failed="1" total="1" passed="0">
  <reporter-output>
  </reporter-output>
  <suite name="Default suite" duration-ms="83106" started-at="2016-03-11T15:00:54Z" finished-at="2016-03-11T15:02:18Z">
    <groups>
      <group name="login">
        <method signature="VerifyMCallLoginAndSearch.loginWithValidUser()[pri:0, instance:com.mcall.TestCases.VerifyMCallLoginAndSearch@1a92922]" name="loginWithValidUser" class="com.mcall.TestCases.VerifyMCallLoginAndSearch"/>
      </group> <!-- login -->
    </groups>
    <test name="Default test" duration-ms="83106" started-at="2016-03-11T15:00:54Z" finished-at="2016-03-11T15:02:18Z">
      <class name="com.mcall.TestCases.VerifyMCallLoginAndSearch">
        <test-method status="PASS" signature="testSetup()[pri:0, instance:com.mcall.TestCases.VerifyMCallLoginAndSearch@1a92922]" name="testSetup" is-config="true" duration-ms="45619" started-at="2016-03-11T20:30:54Z" finished-at="2016-03-11T20:31:40Z">
          <reporter-output>
          </reporter-output>
        </test-method> <!-- testSetup -->
        <test-method status="FAIL" signature="loginWithValidUser()[pri:0, instance:com.mcall.TestCases.VerifyMCallLoginAndSearch@1a92922]" name="loginWithValidUser" duration-ms="37415" started-at="2016-03-11T20:31:40Z" finished-at="2016-03-11T20:32:18Z">
          <exception class="java.lang.AssertionError">
            <message>
              <![CDATA[User is logged in successfully expected [true] but found [true]]]>
            </message>
            <full-stacktrace>
              <![CDATA[java.lang.AssertionError: User is logged in successfully expected [true] but found [true]
	at org.testng.Assert.fail(Assert.java:94)
	at org.testng.Assert.failNotEquals(Assert.java:513)
	at org.testng.Assert.assertEqualsImpl(Assert.java:135)
	at org.testng.Assert.assertEquals(Assert.java:116)
	at com.mcall.TestCases.VerifyMCallLoginAndSearch.loginWithValidUser(VerifyMCallLoginAndSearch.java:67)
	at sun.reflect.NativeMethodAccessorImpl.invoke0(Native Method)
	at sun.reflect.NativeMethodAccessorImpl.invoke(Unknown Source)
	at sun.reflect.DelegatingMethodAccessorImpl.invoke(Unknown Source)
	at java.lang.reflect.Method.invoke(Unknown Source)
	at org.testng.internal.MethodInvocationHelper.invokeMethod(MethodInvocationHelper.java:86)
	at org.testng.internal.Invoker.invokeMethod(Invoker.java:645)
	at org.testng.internal.Invoker.invokeTestMethod(Invoker.java:822)
	at org.testng.internal.Invoker.invokeTestMethods(Invoker.java:1130)
	at org.testng.internal.TestMethodWorker.invokeTestMethods(TestMethodWorker.java:129)
	at org.testng.internal.TestMethodWorker.run(TestMethodWorker.java:112)
	at org.testng.TestRunner.privateRun(TestRunner.java:782)
	at org.testng.TestRunner.run(TestRunner.java:632)
	at org.testng.SuiteRunner.runTest(SuiteRunner.java:366)
	at org.testng.SuiteRunner.runSequentially(SuiteRunner.java:361)
	at org.testng.SuiteRunner.privateRun(SuiteRunner.java:319)
	at org.testng.SuiteRunner.run(SuiteRunner.java:268)
	at org.testng.SuiteRunnerWorker.runSuite(SuiteRunnerWorker.java:52)
	at org.testng.SuiteRunnerWorker.run(SuiteRunnerWorker.java:86)
	at org.testng.TestNG.runSuitesSequentially(TestNG.java:1244)
	at org.testng.TestNG.runSuitesLocally(TestNG.java:1169)
	at org.testng.TestNG.run(TestNG.java:1064)
	at org.testng.remote.RemoteTestNG.run(RemoteTestNG.java:113)
	at org.testng.remote.RemoteTestNG.initAndRun(RemoteTestNG.java:206)
	at org.testng.remote.RemoteTestNG.main(RemoteTestNG.java:177)
]]>
            </full-stacktrace>
          </exception> <!-- java.lang.AssertionError -->
          <reporter-output>
          </reporter-output>
        </test-method> <!-- loginWithValidUser -->
      </class> <!-- com.mcall.TestCases.VerifyMCallLoginAndSearch -->
    </test> <!-- Default test -->
  </suite> <!-- Default suite -->
</testng-results>
